Workbook

Sheet FORMULARIO
A1: MINISTERIO DE TRANSPORTE | T1: FORMULARIO DE SOLICITUD DE TRAMITES DEL REGISTRO NACIONAL AUTOMOTOR | AA1: 1, ORGANISMO DE TRÁNSITO | AJ1: 2. PLACA
AA2: NOMBRE | AJ2: LETRAS | AK2: NÚMEROS
AA3: CIUDAD | AC3: CODIGO | AF3: FECHA DE TRAMITE | AJ3: =DATOS!C19 -> GRV | AK3: =DATOS!D19 -> 119
AF4: DIA | AG4: MES | AH4: AÑO
A6: 3. TRAMITE SOLICITADO | W6: 5. MARCA | Z6: 6. LINEA | AC6: 7.COMBUSTIBLE
A7: 1 | B7: MATRICULA/ REGISTRO | E7: 2 | F7: TRASPASO | I7: 3 | J7: TRANSLADO MATRICULA / REGISTRO | N7: 4 | O7: RADICADO MATRICULA / REGISTRO | Q7: 5 | R7: CAMBIO DE COLOR | T7: 6 | U7: CAMBIO DE SERVICIO | W7: =DATOS!B22 -> RENAULT | Z7: =DATOS!B23 -> SANDERO | AC7: GASOLINA | AE7: DIESEL | AF7: GAS. | AG7: MIXTO | AH7: ELECTRICO | AI7: HIDROGEN. | AJ7: ETANOL | AK7: BIODIESEL
AC8: 1 | AE8: 2 | AF8: 3 | AG8: 4 | AH8: 5 | AI8: 6 | AJ8: 7 | AK8: 8
A9: 7 | B9: REGRABAR MOTOR | E9: 8 | F9: REGRABAR CHASIS | I9: 9 | J9: TRANSFORMACION | N9: 10 | O9: DUPLICADO LICENCIA TRANSITO | Q9: 11 | R9: INSCRIPC. PRENDA | T9: 12 | U9: LEVANTA. PRENDA | W9: 8. COLORES | AG9: 9. MODELO | AI9: 10. CILINDRADA
W10: =DATOS!B24 -> ROJO FUEGO | AG10: =DATOS!B20 -> 2020 | AI10: =DATOS!B34 -> 1598
A12: 13 | B12: CANCELACION MATRICULA / REGISTRO | E12: 14 | F12: CAMBIO DE PLACAS | I12: 15 | J12: DUPLICADO DE PLACAS | N12: 16 | O12: REMATRICULA | Q12: 17 | R12: CAMBIO DE CARROCERIA | T12: 18 | U12: OTROS | W12: 11. CAPACIDAD Kg/Psj | Z12: 12. BLINDAJE SI NO | AE12: 13.DESMONTE BLIND. SI NO | AI12: 14. POTENCIA/HP
W13: =DATOS!B32 -> 5PSJ | Z13: Resolución No (DD/MM/AÑO) | AE13: Resolución No (DD/MM/AÑO) | AI13: =DATOS!B33 -> 85
A15: 4. CLASE DE VEHICULO | W15: 15. CARROCERIA | AE15: 16. IDENTIFICACION INTERNA DEL VEHICULO
A16: AUTOMOVIL | D16: BUS | H16: BUSETA | L16: CAMIÓN | O16: CAMIONETA | P16: CAMPERO | S16: MICROBUS | W16: CODIGO | AE16: No. DE MOTOR | AJ16: REGRABADO
A17: =DATOS!E20 -> X | D17: =DATOS!F20 -> 0 | H17: =DATOS!G20 -> 0 | L17: =DATOS!H20 -> 0 | O17: =DATOS!I20 -> 0 | P17: =DATOS!J20 -> 0 | S17: =DATOS!K20 -> 0 | AE17: =DATOS!B27 -> A812UF91875 | AJ17: SI NO
A18: TRACTOCAMIÓN | D18: MOTOCICLETA | H18: MOTOCARRO | L18: MOTOTRICICLO | O18: CUATRIMOTO | P18: VOLQUETA | S18: OTRO | W18: TIPO | AE18: No. DE CHASIS | AJ18: REGRABADO
A19: =DATOS!E22 -> 0 | D19: =DATOS!F22 -> 0 | H19: =DATOS!G22 -> 0 | L19: =DATOS!H22 -> 0 | O19: =DATOS!I22 -> 0 | P19: =DATOS!J22 -> 0 | S19: =DATOS!K22 -> 0 | AE19: =DATOS!B29 -> 9FB5SREB4LM325716 | AJ19: SI NO
A21: 21. DATOS DEL PROPIETARIO | AE21: No. DE SERIE | AJ21: REGRABADO
W22: 17. IMPORTACIÓN O REMATE | AE22: =DATOS!B28 -> 9FB5SREB4LM325716 | AJ22: SI NO
A23: PRIMER APELLIDO | I23: SEGUNDO APELLIDO | P23: NOMBRES | W23: IMPORTACION | Y23: REMATE | AE23: No. DE VIN VEHICULOS AUTOMOTORES
A24: =DATOS!B3 -> MORENO | I24: =DATOS!C3 -> ROZO | P24: =DATOS!D3 -> LORENA | W24: MANIF. O ACTA 1 | X24: DEC. DE IMPOR. 2 | Y24: ACTA 3 | Z24: ENTIDAD 4 | AA24: LUGAR (CIUDAD) 5 | AB24: CODIGO 6 | AE24: =DATOS!B30 -> 9FB5SREB4LM325716
A25: C.C | C25: NIT | D25: N.N | G25: PASAPORTE | J25: C.EXTRANJ. | L25: T.IDENTI. | O25: NUIP | P25: C. DIPLOMATICO | S25: No. DOCUMENTO
A26: C | C26: N | D26: X | G26: P | J26: E | L26: T | O26: U | P26: D | S26: =DATOS!B4 -> 1110451335 | W26: No. DOCUMENTO | Z26: FECHA
Z27: DIA | AA27: MES | AB27: AÑO | AE27: 18. TIPO DE SERVICIO
A28: DIRECCION | M28: CIUDAD | S28: TELEFONO | AE28: PARTICUL | AF28: PUBLICO | AG28: DIPLOMATI. | AH28: OFICIAL | AI28: ESPECIAL | AJ28: OTROS
A29: =DATOS!B7 -> Cr 8 sur 93 -65 conjunto Altagracia | M29: =DATOS!B8 -> IBAGUE | S29: =DATOS!B5 -> 3183023815 | AE29: 1 | AF29: 2 | AG29: 3 | AH29: 4 | AI29: 5 | AJ29: 6
A30: FIRMA DEL PROPIETARIO
W31: 20. DATOS DE ALERTA | AE31: 19. EMPRESA VINCULADORA
W32: HURTO 1 | X32: LIM. PROPIEDAD 2 | Z32: EMBARGO 3 | AA32: OTRO 4 | AB32: A FAVOR DE: 5 | AE32: NOMBRE | AJ32: NIT
A34: 22. DATOS DEL COMPRADOR (TRASPASO)
A36: PRIMER APELLIDO | I36: SEGUNDO APELLIDO | P36: NOMBRES
A37: =DATOS!B11 -> LOAIZA | I37: =DATOS!C11 -> IDARRAGA | P37: =DATOS!D11 -> LUCELY | W37: 23. OBSERVACIONES
W38: ESPECIFIQUE LA PALABRA OTRO Y TRANSFORMACIÓN EFECTUADA AL VEHICULO, AMPLEI EL TIPO DE ALERTA O LO QUE ESTIME
A40: C.C | C40: NIT | D40: N.N | G40: PASAPORTE | J40: C.EXTRANJ. | L40: T.IDENTI. | O40: NUIP | P40: C. DIPLOMATICO | S40: No. DOCUMENTO
A41: C | C41: N | D41: X | G41: P | J41: E | L41: T | O41: U | P41: D | S41: =DATOS!B12 -> 52536644
A43: DIRECCION | M43: CIUDAD | S43: TELEFONO | W43: OBSERVACIONES (PARA TRASPASO DE VEHICULOS AUTOMOTORES ANTES DE RUNT)
A44: =DATOS!B15 -> Mnz e casa 22 barrio entre ríos | M44: =DATOS!B16 -> ESPINAL | S44: =DATOS!B13 -> 3102925585 | W44: SI SU VEHICULO AUTOMOTOR HA SIDO MATRICULADO ANTES DEL RUNT TRANSCRIBA EN ESTE CAMPO EL TIPO DE CARROCERIA Y LA CLASE DE VEHICULO QUE SE ENCUENTRA REGISTRADA EN SU LICENCIA DE TRÁNSITO O CUALQUIER OTRO ASPECTO QUE CONSIDERE NECESARIO PARA DAR EXACTITUD A LA INFORMACIÓN.
A45: FIRMA DEL COMPRADOR
A48: NOTA: VER INSTRUCCIONES AL RESPALDO
A51: INSTRUCCIONES
A52: EL FORMULARIO DE SOLICITUD DE TRAMITES DE VEHICULOS, ES UN DOCUMENTO A TRAVÉS DEL CUAL LA PERSONA NATURAL O JURÍDICA SOLICITA ANTE LA AUTORIDAD COMPETENTE, LA REALIZACIÒN DE UN TRÁMITE.
...

Sheet  MANDATO
I2: CONTRATO DE MANDATO
C5: Entre los suscritos a saber | H5: =CONCATENATE(DATOS!B3," ",DATOS!C3," ",DATOS!D3) -> MORENO ROZO LORENA | Q5: mayor de edad, vecino
C7: de esta cuidad,identificado con cedula de ciudadanía | M7: =DATOS!B4 -> 1110451335 | Q7: quien para efectos del
C9: presente contrato se denominará EL MANDANTE, y de otro
H11: También mayor de edad, vecino de la esta ciudad, cédula de
C13: Ciudadanía No. ,quien para efectos del presente contrato se denominará EL | I13: , quien para efectos del presente contrato se denominará EL
C15: MANDATARIO, Hemos acordado suscribir el siguiente contrato de mandato cumpliendo con
C17: la Resolución 12379 expedida por el Ministerio de Transporte el 28 de diciembre de 2012
C19: (Art.5), que se regirá por la normas civiles y comerciales que regulan la materia de Concordancia
C21: con el Art. 2149 C.C según las siguientes cláusulas.
C23: PRIMERA: OBJETO DEL CONTRATO. EL MANDATARIO por cuenta y riesgo del MANDANTE
C25: queda facultado para solicitar, realizar, radicar y retirar el trámite | P25: =DATOS!B43 -> TRASPASO
C27: Del vehículo de propiedad del MANDANTE identificado con las siguientes características:
C29: PLACA | E29: =DATOS!B19 -> GRV119 | G29: MARCA | I29: =DATOS!B22 -> RENAULT | L29: LINEA | N29: =DATOS!B23 -> SANDERO | Q29: MODELO | S29: =DATOS!B20 -> 2020
C31: CILINDRAJE | F31: =DATOS!B31 -> 1598 | H31: MOTOR | J31: =DATOS!B27 -> A812UF91875 | N31: CHASIS | P31: =DATOS!B29 -> 9FB5SREB4LM325716
C33: Ante al ORGANIZMOS DE TRANSITO Y TRANSPORTE que corresponda, Como consecuencia,
C35: EL MANDATARIO queda facultado para realizar todas las gestiones propias de este mandato
C37: y en especial para representar, notificarse, recibir, impugnar, desistir, sustituir, reasumir, pedir,
C39: conciliar o asumir obligaciones en nombre del MANDANTE.
C41: SEGUNDA: OBLIGACIONES DEL MANDANTE. EL MANDANTE declara que la información
C43: contenida en los documentos que anexan a la solicitud del trámite es veraz y Auténtica, razón
C45: por la que se hace responsable ante la autoridad competente de cualquier irregularidad que los
C47: mismos puedan Contener.
C52: EL MANDANTE
C56: CC
C61: EL MANDATARIO
C65: CC

Sheet COMPRAVENTA
A2: CONTRATO DE COMPRAVENTA DE VEHICULO AUTOMOTOR
B4: LUGAR Y FECHA DE CELEBRACION DEL CONTRATO: | J4: =CONCATENATE(DATOS!E26," ",DATOS!F26,"/",DATOS!G26,"/",DATOS!H26) -> IBAGUE 23/5/2026
B6: NOMBRE VENDEDOR: | F6: =CONCATENATE(DATOS!B3," ",DATOS!C3," ",DATOS!D3) -> MORENO ROZO LORENA
B7: IDENTIFICACION: | F7: =DATOS!B5 -> 3183023815
B8: DIRECCION: | F8: =DATOS!B7 -> Cr 8 sur 93 -65 conjunto Altagracia
B9: CELULAR: | F9: =DATOS!B5 -> 3183023815
B10: CORREO ELECTRONICO: | F10: =DATOS!B6 -> loremapamati3@gmail.com
B12: NOMBRE COMPRADOR: | F12: =CONCATENATE(DATOS!B11," ",DATOS!C11," ",DATOS!D11) -> LOAIZA IDARRAGA LUCELY
B13: IDENTIFICACION: | F13: =DATOS!B12 -> 52536644
B14: DIRECCION: | F14: =DATOS!B15 -> Mnz e casa 22 barrio entre ríos
B15: CELULAR: | F15: =DATOS!B13 -> 3102925585
B16: CORREO ELECTRONICO: | F16: =DATOS!B14 -> Lucelyloaiza07@gmail.com
B19: LAS PARTES CONVIENEN CELEBRAR EL PRESENTE CONTRATO DE COMPRAVENTA, QUE SE REGIRA
B21: POR LAS ANTERIORES ESTIPULACIONES, LAS NORMAS LEGALES APLICABLESA LA MATERIA Y EN
B23: ESPECIAL POR LAS SIGUIENTES CLAUSULAS : PRIMERA : OBJETO DEL CONTRATO: EL VENDEDOR
B25: TRANSFIERE A TITULO DE VENTA Y EL COMPRADOR ADQUIERE A LA PROPIEDAD DEL VEHICULO
B27: AUTOMOTOR QUE A CONTINUACION SE IDENTIFICA:
B29: PLACAS: | F29: =DATOS!B19 -> GRV119
B30: MODELO: | F30: =DATOS!B20 -> 2020
B31: CLASE: | F31: =DATOS!B21 -> AUTOMOVIL
B32: MARCA: | F32: =DATOS!B22 -> RENAULT
B33: LINEA: | F33: =DATOS!B23 -> SANDERO
B34: COLOR: | F34: =DATOS!B24 -> ROJO FUEGO
B35: PUERTAS: | F35: =DATOS!B25 -> 5
B36: SERVICIO: | F36: =DATOS!B26 -> PARTICULAR
B37: MOTOR NO: | F37: =DATOS!B27 -> A812UF91875
B38: CHASIS: | F38: =DATOS!B29 -> 9FB5SREB4LM325716
B41: SEGUNDA : PRECIO : COMO PRECIO DEL AUTOMOTOR LAS PARTES ACUERDAN LA SUMA DE :
B43: =DATOS!B40 -> 30000000
B45: TERCERA : FORMA DE PAGO : EL COMPRADOR SE COMPROMETE A PAGAR EL PRECIO A QUE SE
B47: REFIERE LA CLAUSULA ANTERIOR DE LA SIGUIENTE FORMA: | K47: =DATOS!B41 -> EFCTIVO
B51: CUARTA: OBLIGACIONES DEL VENDEDOR: HACE ENTREGA DEL VEHICULO LIBRE DE GRAVAMENES,
B53: EMBARGOS, MULTAS, IMPUESTOS, COMPARENDOS DE TRANSITO, PACTOS DE RESERVA DE DOMINIO
B55: Y CUALQUIER OTRA CIRCUNSTANCIA QUE AFECTE EL LIBRE COMERCIO DEL BIEN OBJETO DEL
B57: PRESENTE CONTRATO.
B62: QUINTA: ENTREGA: EN LA FECHA | H62: =CONCATENATE(DATOS!F26,"/",DATOS!G26,"/",DATOS!H26) -> 23/5/2026 | J62: EL VENDEDOR HACE ENTREGA MATERIAL
B64: DEL VEHICULO OBJETO DEL PRESENTE CONTRATO AL COMPRADOR, Y ESTE ASI LO ACEPTA Y
B66: DECLARA QUE CONOCE EL ESTADO EN QUE SE ENCUENTRA EL BIEN OBJETO DE ESTE CONTRATO.
B68: SEXTA: RESPONSABILIDAD: SERÁ IMPUTABLE AL COMPRADOR TODA RESPONSABILIDAD DESDE EL
B70: MOMENTO DE LA ENTREGA MATERIAL Y HASTA EL TRASPASO DEL VEHÍCULO DE PLACA | O70: =DATOS!B19 -> GRV119
...

Sheet DATOS
A1: DATOS TRASPASO | E1: MATRÍCULA/ REGISTRO | F1: TRASPASO | G1: TRANSLADO MATRICULA/ REGISTRO | H1: RADICADO MATRICULA/ REGISTRO | I1: CAMBIO DE COLOR | J1: CAMBIO DE SERVICIO
A2: VENDEDOR | B2: 1 APELLIDO | C2: 2 APELLIDO | D2: NOMBRE
A3: NOMBRE
A4: CEDULA
A5: CELULAR | E5: REGRABAR MOTOR | F5: REGRABAR CHASIS | G5: TRANSFORMACIÓN | H5: DUPLICADO LICENCIA TRANSITO | I5: INSCRIPC. PRENDA | J5: LEVANTA PRENDA
A6: CORREO
A7: DIRECCION
A8: CUIDAD
E9: CANCELACIÓN MATRICULA/ REGISTRO | F9: CAMBIO DE PLACAS | G9: DUPLICADO DE PLACAS | H9: REMATRICULA | I9: CAMBIO DE CARROCERÍA | J9: OTROS
A10: COMPRADOR | B10: 1 APELLIDO | C10: 2 APELLIDO | D10: NOMBRE
A11: NOMBRE
A12: CEDULA
A13: CELULAR
A14: CORREO
A15: DIRECCION
A16: CUIDAD
A18: DATOS DEL VEHICULO | C18: LETRAS | D18: NUMEROS | E18: CLASE DE VEHICULO
A19: PLACAS: | E19: AUTOMOVIL | F19: BUS | G19: BUSETA | H19: CAMION | I19: CAMIONETA | J19: CAMPERO | K19: MICROBUS
A20: MODELO:
A21: CLASE: | E21: TRACTO | F21: MOTOCICLETA | G21: MOTOCARRO | H21: MOTOTRICICLO | I21: CUATRIMOTO | J21: VOLQUETA | K21: OTRO
A22: MARCA:
A23: LINEA:
A24: COLOR:
A25: PUERTAS: | E25: FECHA | F25: DIA | G25: MES | H25: AÑO
A26: SERVICIO:
A27: MOTOR NO:
A28: SERIE:
A29: CHASIS | H29: =IF(F4="X",G9,"REVISE") -> DUPLICADO DE PLACAS
A30: VIN
A31: CILINDRAJE
A32: PASAJERO O CARGA
A33: POTENCIA
A34: CILINDRAJE
A39: OTROS DATOS
A40: VALOR DEL VEHICULO
A41: FORMA DE PAGO
A42: FECHA DE ENTREGA DEL VEHICULO
A43: TIPO DE SERVICIO
A44: DESTRATE

Sheet CHECK LIST
A6: LIQUIDACION DE TRAMITES DEL CENTRO
H7: IMPUESTOS
A8: RETENCION | D8: TARJETA DE PROPIEDAD | H8: TRASPASOS
A9: DERECHOS DE TRASPASO | D9: SOAT | H9: SOAT
A10: PAZ Y SALVO | D10: FOTOCOPIA CEDULA
A11: LEVANTAMIENTO DE PRENDA | D11: RUNT VENDEDOR
A12: INSCRIPCION DE PRENDA | D12: RUNT COMPRADOR
A13: PAPELRIA | D13: ANTECEDENTES COMPRADOR
A14: HONORARIOS | D14: ANTECEDENTES VENDEDOR
A15: IMPUESTO AÑO ACTUAL | D15: LEVAN PRENDA ORIGINAL
A16: IMPUESTO AÑOS VENCIDO | D16: INSCRIBE PRENDA ORIGINAL
D17: CAMARA COMERCIO
D18: CERTIFICADO IMPUESTOS
D19: DECLARACION EXTRAJUICIO
D20: PAZ Y SALVO EMPRESA
D21: CESION DERECHO EMPRESA
